

logging_logger - ERROR - list index out of range
Traceback (most recent call last):
  File "D:/Coding_Projects/my_tools/_practice/logging_lab/logging_module.py", line 52, in <module>
    val = a[4]
IndexError: list index out of range
logging_logger - ERROR - Error: Traceback (most recent call last):
  File "D:/Coding_Projects/my_tools/_practice/logging_lab/logging_module.py", line 60, in <module>
    val = a[4]
IndexError: list index out of range

logging_logger - ERROR - list index out of range
Traceback (most recent call last):
  File "D:/Coding_Projects/my_tools/_practice/logging_lab/logging_module.py", line 52, in <module>
    val = a[4]
IndexError: list index out of range
logging_logger - ERROR - Error: Traceback (most recent call last):
  File "D:/Coding_Projects/my_tools/_practice/logging_lab/logging_module.py", line 60, in <module>
    val = a[4]
IndexError: list index out of range

logging_logger - ERROR - list index out of range
Traceback (most recent call last):
  File "D:/Coding_Projects/my_tools/_practice/logging_lab/logging_module.py", line 52, in <module>
    val = a[4]
IndexError: list index out of range
logging_logger - ERROR - Error: Traceback (most recent call last):
  File "D:/Coding_Projects/my_tools/_practice/logging_lab/logging_module.py", line 60, in <module>
    val = a[4]
IndexError: list index out of range

